Workbook

Sheet Сводка по направлениям
A1: № | B1: ID_Направление | C1: Направление бизнеса | D1: Подразделение в орг. структуре | E1: ID_Руководитель | F1: Руководитель направления | G1: ID_HR_BP | H1: HR BP | I1: Компаний-конкурентов | J1: Типовых должностей
A2: 1 | B2: Н1 | C2: =VLOOKUP(B2,Справочник!$A$2:$B$23,2,FALSE) -> Главная лаборатория | D2: Главная лаборатория | E2: Ч35 | F2: =VLOOKUP(E2,Справочник!$D$2:$E$119,2,FALSE) -> Исломов Чамшед Абдукахорович | G2: Ч32 | H2: =VLOOKUP(G2,Справочник!$D$2:$E$119,2,FALSE) -> Зокирова Зебочон Абдуазимовна | I2: 3 | J2: 13
A3: 2 | B3: Н2 | C3: =VLOOKUP(B3,Справочник!$A$2:$B$23,2,FALSE) -> Департамент бройлерного направления | D3: Департамент бройлерного направления | E3: Ч73 | F3: =VLOOKUP(E3,Справочник!$D$2:$E$119,2,FALSE) -> Рустамов Рахимджон Мухамадович | G3: Ч21 | H3: =VLOOKUP(G3,Справочник!$D$2:$E$119,2,FALSE) -> Боев Иброхимчон Далерович | I3: 18 | J3: 54
A4: 3 | B4: Н3 | C4: =VLOOKUP(B4,Справочник!$A$2:$B$23,2,FALSE) -> Департамент Дистрибуции | D4: Департамент дистрибуции | E4: Ч95 | F4: =VLOOKUP(E4,Справочник!$D$2:$E$119,2,FALSE) -> Хасанов Фарход Сулаймонович | G4: Ч40 | H4: =VLOOKUP(G4,Справочник!$D$2:$E$119,2,FALSE) -> Кодиров Камолчон Насимчонович | I4: 11 | J4: 13
A5: 4 | B5: Н4 | C5: =VLOOKUP(B5,Справочник!$A$2:$B$23,2,FALSE) -> Департамент логистики и ГП | D5: Департамент снабжения и логистики | E5: Ч63 | F5: =VLOOKUP(E5,Справочник!$D$2:$E$119,2,FALSE) -> Пономарев Олег Александрович | G5: Ч32 | H5: =VLOOKUP(G5,Справочник!$D$2:$E$119,2,FALSE) -> Зокирова Зебочон Абдуазимовна | I5: 4 | J5: 10
A6: 5 | B6: Н5 | C6: =VLOOKUP(B6,Справочник!$A$2:$B$23,2,FALSE) -> Департамент по работе с государственными органами | D6: Департамент по работе с государственными органами | E6: Ч80 | F6: =VLOOKUP(E6,Справочник!$D$2:$E$119,2,FALSE) -> Самандаров Исроилхоча Вохидхочаевич | G6: Ч87 | H6: =VLOOKUP(G6,Справочник!$D$2:$E$119,2,FALSE) -> Солиев Умедчон Абдучалолович | I6: 10 | J6: 11
A7: 6 | B7: Н6 | C7: =VLOOKUP(B7,Справочник!$A$2:$B$23,2,FALSE) -> Департамент продажи муки (Опт) | D7: Департамент оптовых продаж | E7: Ч89 | F7: =VLOOKUP(E7,Справочник!$D$2:$E$119,2,FALSE) -> Урунов Акмалхуча Абдуллоевич | G7: Ч40 | H7: =VLOOKUP(G7,Справочник!$D$2:$E$119,2,FALSE) -> Кодиров Камолчон Насимчонович | I7: 16 | J7: 9
A8: 7 | B8: Н7 | C8: =VLOOKUP(B8,Справочник!$A$2:$B$23,2,FALSE) -> Департамент Развития | D8: Департамент развития | E8: Ч10 | F8: =VLOOKUP(E8,Справочник!$D$2:$E$119,2,FALSE) -> Ахроров Ахрорхон Аълохонович | G8: Ч116 | H8: =VLOOKUP(G8,Справочник!$D$2:$E$119,2,FALSE) -> Каримов Дилшодчон Зафарчонович | I8: 8 | J8: 21
A9: 8 | B9: Н8 | C9: =VLOOKUP(B9,Справочник!$A$2:$B$23,2,FALSE) -> Департамент Снабжения | D9: Департамент снабжения и логистики | E9: Ч63 | F9: =VLOOKUP(E9,Справочник!$D$2:$E$119,2,FALSE) -> Пономарев Олег Александрович | G9: Ч32 | H9: =VLOOKUP(G9,Справочник!$D$2:$E$119,2,FALSE) -> Зокирова Зебочон Абдуазимовна | I9: 11 | J9: 12
A10: 9 | B10: Н9 | C10: =VLOOKUP(B10,Справочник!$A$2:$B$23,2,FALSE) -> Дивизион масла | D10: Дивизион производства масла | E10: Ч8 | F10: =VLOOKUP(E10,Справочник!$D$2:$E$119,2,FALSE) -> Ахмедбоев Мубинчон Мукимчонович | G10: Ч32 | H10: =VLOOKUP(G10,Справочник!$D$2:$E$119,2,FALSE) -> Зокирова Зебочон Абдуазимовна | I10: 16 | J10: 17
A11: 10 | B11: Н10 | C11: =VLOOKUP(B11,Справочник!$A$2:$B$23,2,FALSE) -> Дивизион МК | D11: Дивизион производства металлоизделий | E11: Ч79 | F11: =VLOOKUP(E11,Справочник!$D$2:$E$119,2,FALSE) -> Самандаров Исмоилхоча Вохидхочаевич | G11: Ч83 | H11: =VLOOKUP(G11,Справочник!$D$2:$E$119,2,FALSE) -> Собиров Аличон Лахаевич | I11: 3 | J11: 33
A12: 11 | B12: Н11 | C12: =VLOOKUP(B12,Справочник!$A$2:$B$23,2,FALSE) -> Дивизион Птицефабрики | D12: Птицефабрика яичного производства Д1 | E12: Ч23 | F12: =VLOOKUP(E12,Справочник!$D$2:$E$119,2,FALSE) -> Валиев Максудчон Абдуганиевич | G12: Ч21 | H12: =VLOOKUP(G12,Справочник!$D$2:$E$119,2,FALSE) -> Боев Иброхимчон Далерович | I12: 11 | J12: 15
A13: 12 | B13: Н12 | C13: =VLOOKUP(B13,Справочник!$A$2:$B$23,2,FALSE) -> Отдел маркетинга | D13: Департамент маркетинга | E13: Ч7 | F13: =VLOOKUP(E13,Справочник!$D$2:$E$119,2,FALSE) -> Афанасьева Людмила Владимеровна | G13: Ч116 | H13: =VLOOKUP(G13,Справочник!$D$2:$E$119,2,FALSE) -> Каримов Дилшодчон Зафарчонович | I13: 6 | J13: 21
... A23: 22 | B23: Н22 | C23: =VLOOKUP(B23,Справочник!$A$2:$B$23,2,FALSE) -> Финансовый департамент | D23: Финансовый департамент | E23: Ч13 | F23: =VLOOKUP(E23,Справочник!$D$2:$E$119,2,FALSE) -> Бабаджанов Бахромхон | G23: Ч118 | H23: =VLOOKUP(G23,Справочник!$D$2:$E$119,2,FALSE) -> Шукурова Мадинахон Анваровна | I23: 17 | J23: 36

Sheet Компании по направлениям
A1: № | B1: ID_Направление | C1: Направление бизнеса | D1: ID_Руководитель | E1: Руководитель направления | F1: ID_HR_BP | G1: HR BP | H1: ID_Компания | I1: Компания-конкурент
A2: 1 | B2: Н1 | C2: =VLOOKUP(B2,Справочник!$A$2:$B$23,2,FALSE) -> Главная лаборатория | D2: Ч35 | E2: =VLOOKUP(D2,Справочник!$D$2:$E$119,2,FALSE) -> Исломов Чамшед Абдукахорович | F2: Ч32 | G2: =VLOOKUP(F2,Справочник!$D$2:$E$119,2,FALSE) -> Зокирова Зебочон Абдуазимовна | H2: К1 | I2: =VLOOKUP(H2,Справочник!$H$2:$I$164,2,FALSE) -> Молочная радость (Афзал)
A3: 2 | B3: Н1 | C3: =VLOOKUP(B3,Справочник!$A$2:$B$23,2,FALSE) -> Главная лаборатория | D3: Ч35 | E3: =VLOOKUP(D3,Справочник!$D$2:$E$119,2,FALSE) -> Исломов Чамшед Абдукахорович | F3: Ч32 | G3: =VLOOKUP(F3,Справочник!$D$2:$E$119,2,FALSE) -> Зокирова Зебочон Абдуазимовна | H3: К2 | I3: =VLOOKUP(H3,Справочник!$H$2:$I$164,2,FALSE) -> ҶДММ "Орди Фатир"
A4: 3 | B4: Н1 | C4: =VLOOKUP(B4,Справочник!$A$2:$B$23,2,FALSE) -> Главная лаборатория | D4: Ч35 | E4: =VLOOKUP(D4,Справочник!$D$2:$E$119,2,FALSE) -> Исломов Чамшед Абдукахорович | F4: Ч32 | G4: =VLOOKUP(F4,Справочник!$D$2:$E$119,2,FALSE) -> Зокирова Зебочон Абдуазимовна | H4: К3 | I4: =VLOOKUP(H4,Справочник!$H$2:$I$164,2,FALSE) -> ҶДММ "СеганҶ"
A5: 4 | B5: Н2 | C5: =VLOOKUP(B5,Справочник!$A$2:$B$23,2,FALSE) -> Департамент бройлерного направления | D5: Ч73 | E5: =VLOOKUP(D5,Справочник!$D$2:$E$119,2,FALSE) -> Рустамов Рахимджон Мухамадович | F5: Ч21 | G5: =VLOOKUP(F5,Справочник!$D$2:$E$119,2,FALSE) -> Боев Иброхимчон Далерович | H5: К4 | I5: =VLOOKUP(H5,Справочник!$H$2:$I$164,2,FALSE) -> Азиза
A6: 5 | B6: Н2 | C6: =VLOOKUP(B6,Справочник!$A$2:$B$23,2,FALSE) -> Департамент бройлерного направления | D6: Ч73 | E6: =VLOOKUP(D6,Справочник!$D$2:$E$119,2,FALSE) -> Рустамов Рахимджон Мухамадович | F6: Ч21 | G6: =VLOOKUP(F6,Справочник!$D$2:$E$119,2,FALSE) -> Боев Иброхимчон Далерович | H6: К5 | I6: =VLOOKUP(H6,Справочник!$H$2:$I$164,2,FALSE) -> Байзо
A7: 6 | B7: Н2 | C7: =VLOOKUP(B7,Справочник!$A$2:$B$23,2,FALSE) -> Департамент бройлерного направления | D7: Ч73 | E7: =VLOOKUP(D7,Справочник!$D$2:$E$119,2,FALSE) -> Рустамов Рахимджон Мухамадович | F7: Ч21 | G7: =VLOOKUP(F7,Справочник!$D$2:$E$119,2,FALSE) -> Боев Иброхимчон Далерович | H7: К6 | I7: =VLOOKUP(H7,Справочник!$H$2:$I$164,2,FALSE) -> Баракат
A8: 7 | B8: Н2 | C8: =VLOOKUP(B8,Справочник!$A$2:$B$23,2,FALSE) -> Департамент бройлерного направления | D8: Ч73 | E8: =VLOOKUP(D8,Справочник!$D$2:$E$119,2,FALSE) -> Рустамов Рахимджон Мухамадович | F8: Ч21 | G8: =VLOOKUP(F8,Справочник!$D$2:$E$119,2,FALSE) -> Боев Иброхимчон Далерович | H8: К7 | I8: =VLOOKUP(H8,Справочник!$H$2:$I$164,2,FALSE) -> Ганчи Сомон
A9: 8 | B9: Н2 | C9: =VLOOKUP(B9,Справочник!$A$2:$B$23,2,FALSE) -> Департамент бройлерного направления | D9: Ч73 | E9: =VLOOKUP(D9,Справочник!$D$2:$E$119,2,FALSE) -> Рустамов Рахимджон Мухамадович | F9: Ч21 | G9: =VLOOKUP(F9,Справочник!$D$2:$E$119,2,FALSE) -> Боев Иброхимчон Далерович | H9: К8 | I9: =VLOOKUP(H9,Справочник!$H$2:$I$164,2,FALSE) -> Далерон
A10: 9 | B10: Н2 | C10: =VLOOKUP(B10,Справочник!$A$2:$B$23,2,FALSE) -> Департамент бройлерного направления | D10: Ч73 | E10: =VLOOKUP(D10,Справочник!$D$2:$E$119,2,FALSE) -> Рустамов Рахимджон Мухамадович | F10: Ч21 | G10: =VLOOKUP(F10,Справочник!$D$2:$E$119,2,FALSE) -> Боев Иброхимчон Далерович | H10: К9 | I10: =VLOOKUP(H10,Справочник!$H$2:$I$164,2,FALSE) -> Зарнисор
A11: 10 | B11: Н2 | C11: =VLOOKUP(B11,Справочник!$A$2:$B$23,2,FALSE) -> Департамент бройлерного направления | D11: Ч73 | E11: =VLOOKUP(D11,Справочник!$D$2:$E$119,2,FALSE) -> Рустамов Рахимджон Мухамадович | F11: Ч21 | G11: =VLOOKUP(F11,Справочник!$D$2:$E$119,2,FALSE) -> Боев Иброхимчон Далерович | H11: К10 | I11: =VLOOKUP(H11,Справочник!$H$2:$I$164,2,FALSE) -> Икбол
A12: 11 | B12: Н2 | C12: =VLOOKUP(B12,Справочник!$A$2:$B$23,2,FALSE) -> Департамент бройлерного направления | D12: Ч73 | E12: =VLOOKUP(D12,Справочник!$D$2:$E$119,2,FALSE) -> Рустамов Рахимджон Мухамадович | F12: Ч21 | G12: =VLOOKUP(F12,Справочник!$D$2:$E$119,2,FALSE) -> Боев Иброхимчон Далерович | H12: К11 | I12: =VLOOKUP(H12,Справочник!$H$2:$I$164,2,FALSE) -> Мармари
A13: 12 | B13: Н2 | C13: =VLOOKUP(B13,Справочник!$A$2:$B$23,2,FALSE) -> Департамент бройлерного направления | D13: Ч73 | E13: =VLOOKUP(D13,Справочник!$D$2:$E$119,2,FALSE) -> Рустамов Рахимджон Мухамадович | F13: Ч21 | G13: =VLOOKUP(F13,Справочник!$D$2:$E$119,2,FALSE) -> Боев Иброхимчон Далерович | H13: К12 | I13: =VLOOKUP(H13,Справочник!$H$2:$I$164,2,FALSE) -> Мурги Аълосифат
... A232: 231 | B232: Н22 | C232: =VLOOKUP(B232,Справочник!$A$2:$B$23,2,FALSE) -> Финансовый департамент | D232: Ч13 | E232: =VLOOKUP(D232,Справочник!$D$2:$E$119,2,FALSE) -> Бабаджанов Бахромхон | F232: Ч118 | G232: =VLOOKUP(F232,Справочник!$D$2:$E$119,2,FALSE) -> Шукурова Мадинахон Анваровна | H232: К64 | I232: =VLOOKUP(H232,Справочник!$H$2:$I$164,2,FALSE) -> LEGA

Sheet Должности по направлениям
A1: № | B1: ID_Направление | C1: Направление бизнеса | D1: ID_Руководитель | E1: Руководитель направления | F1: ID_Должность | G1: Должность
A2: 1 | B2: Н1 | C2: =VLOOKUP(B2,Справочник!$A$2:$B$23,2,FALSE) -> Главная лаборатория | D2: Ч35 | E2: =VLOOKUP(D2,Справочник!$D$2:$E$119,2,FALSE) -> Исломов Чамшед Абдукахорович | F2: Д1 | G2: =VLOOKUP(F2,Справочник!$K$2:$L$245,2,FALSE) -> ведущий Лаборант
A3: 2 | B3: Н1 | C3: =VLOOKUP(B3,Справочник!$A$2:$B$23,2,FALSE) -> Главная лаборатория | D3: Ч35 | E3: =VLOOKUP(D3,Справочник!$D$2:$E$119,2,FALSE) -> Исломов Чамшед Абдукахорович | F3: Д2 | G3: =VLOOKUP(F3,Справочник!$K$2:$L$245,2,FALSE) -> врач-лаборант
A4: 3 | B4: Н1 | C4: =VLOOKUP(B4,Справочник!$A$2:$B$23,2,FALSE) -> Главная лаборатория | D4: Ч35 | E4: =VLOOKUP(D4,Справочник!$D$2:$E$119,2,FALSE) -> Исломов Чамшед Абдукахорович | F4: Д3 | G4: =VLOOKUP(F4,Справочник!$K$2:$L$245,2,FALSE) -> Заведующий лабораторией
A5: 4 | B5: Н1 | C5: =VLOOKUP(B5,Справочник!$A$2:$B$23,2,FALSE) -> Главная лаборатория | D5: Ч35 | E5: =VLOOKUP(D5,Справочник!$D$2:$E$119,2,FALSE) -> Исломов Чамшед Абдукахорович | F5: Д4 | G5: =VLOOKUP(F5,Справочник!$K$2:$L$245,2,FALSE) -> инжинер по качеству
A6: 5 | B6: Н1 | C6: =VLOOKUP(B6,Справочник!$A$2:$B$23,2,FALSE) -> Главная лаборатория | D6: Ч35 | E6: =VLOOKUP(D6,Справочник!$D$2:$E$119,2,FALSE) -> Исломов Чамшед Абдукахорович | F6: Д5 | G6: =VLOOKUP(F6,Справочник!$K$2:$L$245,2,FALSE) -> Лаборант
A7: 6 | B7: Н1 | C7: =VLOOKUP(B7,Справочник!$A$2:$B$23,2,FALSE) -> Главная лаборатория | D7: Ч35 | E7: =VLOOKUP(D7,Справочник!$D$2:$E$119,2,FALSE) -> Исломов Чамшед Абдукахорович | F7: Д6 | G7: =VLOOKUP(F7,Справочник!$K$2:$L$245,2,FALSE) -> Менеджер
A8: 7 | B8: Н1 | C8: =VLOOKUP(B8,Справочник!$A$2:$B$23,2,FALSE) -> Главная лаборатория | D8: Ч35 | E8: =VLOOKUP(D8,Справочник!$D$2:$E$119,2,FALSE) -> Исломов Чамшед Абдукахорович | F8: Д7 | G8: =VLOOKUP(F8,Справочник!$K$2:$L$245,2,FALSE) -> микробиолог
A9: 8 | B9: Н1 | C9: =VLOOKUP(B9,Справочник!$A$2:$B$23,2,FALSE) -> Главная лаборатория | D9: Ч35 | E9: =VLOOKUP(D9,Справочник!$D$2:$E$119,2,FALSE) -> Исломов Чамшед Абдукахорович | F9: Д8 | G9: =VLOOKUP(F9,Справочник!$K$2:$L$245,2,FALSE) -> Начальник отдела
A10: 9 | B10: Н1 | C10: =VLOOKUP(B10,Справочник!$A$2:$B$23,2,FALSE) -> Главная лаборатория | D10: Ч35 | E10: =VLOOKUP(D10,Справочник!$D$2:$E$119,2,FALSE) -> Исломов Чамшед Абдукахорович | F10: Д9 | G10: =VLOOKUP(F10,Справочник!$K$2:$L$245,2,FALSE) -> Пекарь
A11: 10 | B11: Н1 | C11: =VLOOKUP(B11,Справочник!$A$2:$B$23,2,FALSE) -> Главная лаборатория | D11: Ч35 | E11: =VLOOKUP(D11,Справочник!$D$2:$E$119,2,FALSE) -> Исломов Чамшед Абдукахорович | F11: Д10 | G11: =VLOOKUP(F11,Справочник!$K$2:$L$245,2,FALSE) -> Руководитель
A12: 11 | B12: Н1 | C12: =VLOOKUP(B12,Справочник!$A$2:$B$23,2,FALSE) -> Главная лаборатория | D12: Ч35 | E12: =VLOOKUP(D12,Справочник!$D$2:$E$119,2,FALSE) -> Исломов Чамшед Абдукахорович | F12: Д11 | G12: =VLOOKUP(F12,Справочник!$K$2:$L$245,2,FALSE) -> Специалист ОТК
A13: 12 | B13: Н1 | C13: =VLOOKUP(B13,Справочник!$A$2:$B$23,2,FALSE) -> Главная лаборатория | D13: Ч35 | E13: =VLOOKUP(D13,Справочник!$D$2:$E$119,2,FALSE) -> Исломов Чамшед Абдукахорович | F13: Д12 | G13: =VLOOKUP(F13,Справочник!$K$2:$L$245,2,FALSE) -> Старший лаборант
... A384: 383 | B384: Н22 | C384: =VLOOKUP(B384,Справочник!$A$2:$B$23,2,FALSE) -> Финансовый департамент | D384: Ч13 | E384: =VLOOKUP(D384,Справочник!$D$2:$E$119,2,FALSE) -> Бабаджанов Бахромхон | F384: Д244 | G384: =VLOOKUP(F384,Справочник!$K$2:$L$245,2,FALSE) -> Экономист

Sheet Ответственные лица
A1: № | B1: ID_Человек | C1: ФИО | D1: ID_Бизнес | E1: Направление | F1: Роль | G1: Примечание / расхождение
A2: 1 | B2: Ч1 | C2: =VLOOKUP(B2,Справочник!$D$2:$E$119,2,FALSE) -> Абдувахобов Абдували Абдуазизович | D2: 11 | E2: Департамент Дистрибуции
A3: 2 | B3: Ч2 | C3: =VLOOKUP(B3,Справочник!$D$2:$E$119,2,FALSE) -> Абдувохидов Чамшед Шарифчонович | D3: 2 | E3: Дивизион строительного направления (РБУ / Кирпичзавод / ЖБИ / Гравий)
A4: 3 | B4: Ч3 | C4: =VLOOKUP(B4,Справочник!$D$2:$E$119,2,FALSE) -> Абдуллоев Гуломчон Иномчонович | D4: 9 | E4: Департамент логистики и ГП
A5: 4 | B5: Ч4 | C5: =VLOOKUP(B5,Справочник!$D$2:$E$119,2,FALSE) -> Азимӣ Хусрав Аъзам | D5: 7 | E5: Департамент Развития
A6: 5 | B6: Ч5 | C6: =VLOOKUP(B6,Справочник!$D$2:$E$119,2,FALSE) -> Акрамов Мирзодаврон Хабибович | D6: 9 | E6: Департамент логистики и ГП
A7: 6 | B7: Ч6 | C7: =VLOOKUP(B7,Справочник!$D$2:$E$119,2,FALSE) -> Арипов Махсуд Махмудович | D7: 15 | E7: Проектный офис
A8: 7 | B8: Ч7 | C8: =VLOOKUP(B8,Справочник!$D$2:$E$119,2,FALSE) -> Афанасьева Людмила Владимеровна | D8: 19 | E8: Отдел маркетинга
A9: 8 | B9: Ч8 | C9: =VLOOKUP(B9,Справочник!$D$2:$E$119,2,FALSE) -> Ахмедбоев Мубинчон Мукимчонович | D9: 4 | E9: Дивизион масла
A10: 9 | B10: Ч9 | C10: =VLOOKUP(B10,Справочник!$D$2:$E$119,2,FALSE) -> Ахмедов Дилшод Гафурович | D10: 13 | E10: Финансовый департамент
A11: 10 | B11: Ч10 | C11: =VLOOKUP(B11,Справочник!$D$2:$E$119,2,FALSE) -> Ахроров Ахрорхон Аълохонович | D11: 7 | E11: Департамент Развития
A12: 11 | B12: Ч11 | C12: =VLOOKUP(B12,Справочник!$D$2:$E$119,2,FALSE) -> Ашуров Азимчон | D12: 4 | E12: Дивизион масла
A13: 12 | B13: Ч12 | C13: =VLOOKUP(B13,Справочник!$D$2:$E$119,2,FALSE) -> Аюбова Зарриначон Комиловна | D13: 13 | E13: Финансовый департамент
... A19: 18 | B19: Ч18 | C19: =VLOOKUP(B19,Справочник!$D$2:$E$119,2,FALSE) -> Бобохонов Мухаммадшариф | D19: 11 | E19: Департамент Дистрибуции
A20: 19 | B20: Ч19 | C20: =VLOOKUP(B20,Справочник!$D$2:$E$119,2,FALSE) -> Бобочонов Баходур | E20: Правление
A21: 20 | B21: Ч20 | C21: =VLOOKUP(B21,Справочник!$D$2:$E$119,2,FALSE) -> Бобочонов Назар Орифчонович | D21: 14 | E21: Департамент по работе с государственными органами / Административно-хозяйственное управление
A22: 21 | B22: Ч21 | C22: =VLOOKUP(B22,Справочник!$D$2:$E$119,2,FALSE) -> Боев Иброхимчон Далерович | D22: 555 | E22: HR BP (без привязки к направлению) | F22: HR BP
A23: 22 | B23: Ч22 | C23: =VLOOKUP(B23,Справочник!$D$2:$E$119,2,FALSE) -> Бузуруков Хуршед Аточонович | D23: 1 | E23: Производства Муки
A24: 23 | B24: Ч23 | C24: =VLOOKUP(B24,Справочник!$D$2:$E$119,2,FALSE) -> Валиев Максудчон Абдуганиевич | D24: 3 | E24: Дивизион Птицефабрики
A25: 24 | B25: Ч24 | C25: =VLOOKUP(B25,Справочник!$D$2:$E$119,2,FALSE) -> Вохидов Маъруфчон Мавлонович | D25: 10 | E25: Департамент продажи муки (Опт)
A26: 25 | B26: Ч25 | C26: =VLOOKUP(B26,Справочник!$D$2:$E$119,2,FALSE) -> Гафуров Хайрулло Кахорович | D26: 4 | E26: Дивизион масла
A27: 26 | B27: Ч26 | C27: =VLOOKUP(B27,Справочник!$D$2:$E$119,2,FALSE) -> Гоибов Дадочон Бахтиёрович | D27: 12 | E27: Департамент Снабжения
A28: 27 | B28: Ч27 | C28: =VLOOKUP(B28,Справочник!$D$2:$E$119,2,FALSE) -> Денис Салин Александрович | D28: 19 | E28: Отдел маркетинга
A29: 28 | B29: Ч28 | C29: =VLOOKUP(B29,Справочник!$D$2:$E$119,2,FALSE) -> Заболотный Дмитрий | D29: 11 | E29: Департамент Дистрибуции
A30: 29 | B30: Ч29 | C30: =VLOOKUP(B30,Справочник!$D$2:$E$119,2,FALSE) -> Зарифи Мирзобаховаддин Мусозода | D30: 9 | E30: Департамент логистики и ГП
A31: 30 | B31: Ч30 | C31: =VLOOKUP(B31,Справочник!$D$2:$E$119,2,FALSE) -> Зикруллаев Рахимхон | D31: 13 | E31: Финансовый департамент
A32: 31 | B32: Ч31 | C32: =VLOOKUP(B32,Справочник!$D$2:$E$119,2,FALSE) -> Зоидов Аъзамчон Акрамович | D32: 13 | E32: Финансовый департамент
A33: 32 | B33: Ч32 | C33: =VLOOKUP(B33,Справочник!$D$2:$E$119,2,FALSE) -> Зокирова Зебочон Абдуазимовна | D33: 555 | E33: HR BP (без привязки к направлению) | F33: HR BP
A34: 33 | B34: Ч33 | C34: =VLOOKUP(B34,Справочник!$D$2:$E$119,2,FALSE) -> Ибодуллоев Фаридун Умарович | D34: 10 | E34: Департамент продажи муки (Опт)
A35: 34 | B35: Ч34 | C35: =VLOOKUP(B35,Справочник!$D$2:$E$119,2,FALSE) -> Искандаров Хайрулло Абдуллоевич | D35: 1 | E35: Производства Муки
A36: 35 | B36: Ч35 | C36: =VLOOKUP(B36,Справочник!$D$2:$E$119,2,FALSE) -> Исломов Чамшед Абдукахорович | D36: 17 | E36: Главная лаборатория
A37: 36 | B37: Ч36 | C37: =VLOOKUP(B37,Справочник!$D$2:$E$119,2,FALSE) -> Исоматдинов Сайдулло Хабибуллоевич | D37: 10 | E37: Департамент продажи муки (Опт)
A38: 37 | B38: Ч37 | C38: =VLOOKUP(B38,Справочник!$D$2:$E$119,2,FALSE) -> Каримов Мансурчон Рахимчонович | D38: 10 | E38: Департамент продажи муки (Опт)
A39: 38 | B39: Ч38 | C39: =VLOOKUP(B39,Справочник!$D$2:$E$119,2,FALSE) -> Кахоров Абдуманнон Абдукосимович | D39: 13 | E39: Финансовый департамент
A40: 39 | B40: Ч39 | C40: =VLOOKUP(B40,Справочник!$D$2:$E$119,2,FALSE) -> Кенчаев Эминчон Абдуразокович | D40: 6 | E40: Продажа комбикорм / Производства комбикормов
A41: 40 | B41: Ч40 | C41: =VLOOKUP(B41,Справочник!$D$2:$E$119,2,FALSE) -> Кодиров Камолчон Насимчонович | D41: 555 | E41: HR BP (без привязки к направлению) | F41: HR BP
A42: 41 | B42: Ч41 | C42: =VLOOKUP(B42,Справочник!$D$2:$E$119,2,FALSE) -> Косимов Умедчон Гуфрончонович | D42: 13 | E42: Финансовый департамент
A43: 42 | B43: Ч42 | C43: =VLOOKUP(B43,Справочник!$D$2:$E$119,2,FALSE) -> Кучкоров Икром Ильхомжонович | D43: 7 | E43: Департамент Развития
A44: 43 | B44: Ч43 | C44: =VLOOKUP(B44,Справочник!$D$2:$E$119,2,FALSE) -> Мавлонов Шавкат Абдумаликович | D44: 7 | E44: Департамент Развития
A45: 44 | B45: Ч44 | C45: =VLOOKUP(B45,Справочник!$D$2:$E$119,2,FALSE) -> Мавлонов Шахзод Абдумаликович | D45: 13 | E45: Финансовый департамент
...

Sheet Справочник
A1: ID_Направление | B1: Направление бизнеса | D1: ID_Человек | E1: ФИО | F1: Примечание | H1: ID_Компания | I1: Компания-конкурент | K1: ID_Должность | L1: Должность
A2: Н1 | B2: Главная лаборатория | D2: Ч1 | E2: Абдувахобов Абдували Абдуазизович | H2: К1 | I2: Молочная радость (Афзал) | K2: Д1 | L2: ведущий Лаборант
A3: Н2 | B3: Департамент бройлерного направления | D3: Ч2 | E3: Абдувохидов Чамшед Шарифчонович | H3: К2 | I3: ҶДММ "Орди Фатир" | K3: Д2 | L3: врач-лаборант
A4: Н3 | B4: Департамент Дистрибуции | D4: Ч3 | E4: Абдуллоев Гуломчон Иномчонович | H4: К3 | I4: ҶДММ "СеганҶ" | K4: Д3 | L4: Заведующий лабораторией
A5: Н4 | B5: Департамент логистики и ГП | D5: Ч4 | E5: Азимӣ Хусрав Аъзам | H5: К4 | I5: Азиза | K5: Д4 | L5: инжинер по качеству
A6: Н5 | B6: Департамент по работе с государственными органами | D6: Ч5 | E6: Акрамов Мирзодаврон Хабибович | H6: К5 | I6: Байзо | K6: Д5 | L6: Лаборант
A7: Н6 | B7: Департамент продажи муки (Опт) | D7: Ч6 | E7: Арипов Махсуд Махмудович | H7: К6 | I7: Баракат | K7: Д6 | L7: Менеджер
A8: Н7 | B8: Департамент Развития | D8: Ч7 | E8: Афанасьева Людмила Владимеровна | H8: К7 | I8: Ганчи Сомон | K8: Д7 | L8: микробиолог
A9: Н8 | B9: Департамент Снабжения | D9: Ч8 | E9: Ахмедбоев Мубинчон Мукимчонович | H9: К8 | I9: Далерон | K9: Д8 | L9: Начальник отдела
A10: Н9 | B10: Дивизион масла | D10: Ч9 | E10: Ахмедов Дилшод Гафурович | H10: К9 | I10: Зарнисор | K10: Д9 | L10: Пекарь
A11: Н10 | B11: Дивизион МК | D11: Ч10 | E11: Ахроров Ахрорхон Аълохонович | H11: К10 | I11: Икбол | K11: Д10 | L11: Руководитель
A12: Н11 | B12: Дивизион Птицефабрики | D12: Ч11 | E12: Ашуров Азимчон | H12: К11 | I12: Мармари | K12: Д11 | L12: Специалист ОТК
A13: Н12 | B13: Отдел маркетинга | D13: Ч12 | E13: Аюбова Зарриначон Комиловна | H13: К12 | I13: Мурги Аълосифат | K13: Д12 | L13: Старший лаборант
... A23: Н22 | B23: Финансовый департамент | D23: Ч22 | E23: Бузуруков Хуршед Аточонович | H23: К22 | I23: Авангард | K23: Д22 | L23: Главный ветеренарный врач
D24: Ч23 | E24: Валиев Максудчон Абдуганиевич | H24: К23 | I24: Андалеб | K24: Д23 | L24: Главный инженер
D25: Ч24 | E25: Вохидов Маъруфчон Мавлонович | H25: К24 | I25: АЧР | K25: Д24 | L25: Главный технолог
D26: Ч25 | E26: Гафуров Хайрулло Кахорович | H26: К25 | I26: Барс | K26: Д25 | L26: Заведующий хозяйством
D27: Ч26 | E27: Гоибов Дадочон Бахтиёрович | H27: К26 | I27: Зирвеко | K27: Д26 | L27: закладчик яиц
D28: Ч27 | E28: Денис Салин Александрович | H28: К27 | I28: Зухал | K28: Д27 | L28: Заместитель руководителя
D29: Ч28 | E29: Заболотный Дмитрий | H29: К28 | I29: Мусаффо | K29: Д28 | L29: Инженер вент, отопл, водоотведед, водоснабжение
D30: Ч29 | E30: Зарифи Мирзобаховаддин Мусозода | H30: К29 | I30: Сахо | K30: Д29 | L30: Инженер КиП и А - метролог
D31: Ч30 | E31: Зикруллаев Рахимхон | H31: К30 | I31: Таджеро | K31: Д30 | L31: Инженер КИПиА
D32: Ч31 | E32: Зоидов Аъзамчон Акрамович | H32: К31 | I32: Хочи Давлат | K32: Д31 | L32: Инженер механик
D33: Ч32 | E33: Зокирова Зебочон Абдуазимовна | H33: К32 | I33: Хочи Даврон | K33: Д32 | L33: Инженер холодильщик (совмещение с КиПиА)
D34: Ч33 | E34: Ибодуллоев Фаридун Умарович | H34: К33 | I34: Ачр (ГП) | K34: Д33 | L34: Инженер электрик
D35: Ч34 | E35: Искандаров Хайрулло Абдуллоевич | H35: К34 | I35: Буона (ГП) | K35: Д34 | L35: Инспектор по операционому контролю
... D116: Ч115 | E116: Nicolas Jegard | H116: К115 | I116: ЭЛИТ СОХТМОН | K116: Д115 | L116: Стажер
D117: Ч116 | E117: Каримов Дилшодчон Зафарчонович | F117: Новый — отсутствовал в «Ответственные лица», найден только как Руководитель/HR BP в других листах | H117: К116 | I117: Акма | K117: Д116 | L117: Старший специалист
D118: Ч117 | E118: Окилов Баротчон Камолович | F118: Новый — отсутствовал в «Ответственные лица», найден только как Руководитель/HR BP в других листах | H118: К117 | I118: Зам-Зам | K118: Д117 | L118: Юрист
D119: Ч118 | E119: Шукурова Мадинахон Анваровна | F119: Новый — отсутствовал в «Ответственные лица», найден только как Руководитель/HR BP в других листах | H119: К118 | I119: Миллионка Амон | K119: Д118 | L119: HR BP
H120: К119 | I120: Миллионка Нуъмонако | K120: Д119 | L120: HR Generalist
H121: К120 | I121: Миллионка Хитой | K121: Д120 | L121: S HR BP
H122: К121 | I122: Ободкор | K122: Д121 | L122: Весовщик
H123: К122 | I123: Пролетар Заводи калон | K123: Д122 | L123: Директор
H124: К123 | I124: Таксапарк Усмончон | K124: Д123 | L124: Мастер
H125: К124 | I125: АВРУПОСОЗ | K125: Д124 | L125: Начальник склада тары
H126: К125 | I126: Каскад Хучанд | K126: Д125 | L126: Руководитель по развитию
H127: К126 | I127: КИМЁ | K127: Д126 | L127: Заведующей лабораторией
H128: К127 | I128: Кристал сохтмон | K128: Д127 | L128: Кочегар
H129: К128 | I129: НУРИ СИФАТ | K129: Д128 | L129: Начальник цеха
...
